Workbook
Name Indoor: OFFSET([1]Indoor!$A$2,MATCH(Total_Москва!#REF!,[1]Indoor!$A$2:$A$996,0)-1,1,COUNTIF([1]Indoor!$A$2:$A$996,Total_Москва!#REF!),1)
Name Indoor: OFFSET([1]Indoor!$A$2,MATCH('Медиа факторы'!#REF!,[1]Indoor!$A$2:$A$996,0)-1,1,COUNTIF([1]Indoor!$A$2:$A$996,'Медиа факторы'!#REF!),1)
Name Indoor: OFFSET([2]Indoor!$A$2,MATCH(Москва!$E$4,[2]Indoor!$A$2:$A$996,0)-1,1,COUNTIF([2]Indoor!$A$2:$A$996,Москва!$E$4),1)
Name Indoor: OFFSET([1]Indoor!$A$2,MATCH(Фильтры!#REF!,[1]Indoor!$A$2:$A$996,0)-1,1,COUNTIF([1]Indoor!$A$2:$A$996,Фильтры!#REF!),1)
Name Indoor: OFFSET([1]Indoor!$A$2,MATCH(#REF!,[1]Indoor!$A$2:$A$996,0)-1,1,COUNTIF([1]Indoor!$A$2:$A$996,#REF!),1)
Name OTSРадио: OFFSET([1]Радиостанции!$B$1,MATCH(Total_Москва!#REF!,[1]Радиостанции!$B:$B,0)-1,3,COUNTIF([1]Радиостанции!$B:$B,Total_Москва!#REF!),1)
Name OTSРадио: OFFSET([1]Радиостанции!$B$1,MATCH('Медиа факторы'!$C1,[1]Радиостанции!$B:$B,0)-1,3,COUNTIF([1]Радиостанции!$B:$B,'Медиа факторы'!$C1),1)
Name OTSРадио: OFFSET([2]Радиостанции!$B$1,MATCH(Москва!$E1,[2]Радиостанции!$B:$B,0)-1,3,COUNTIF([2]Радиостанции!$B:$B,Москва!$E1),1)
Name OTSРадио: OFFSET([1]Радиостанции!$B$1,MATCH(Фильтры!$B1,[1]Радиостанции!$B:$B,0)-1,3,COUNTIF([1]Радиостанции!$B:$B,Фильтры!$B1),1)
Name OTSРадио: OFFSET([1]Радиостанции!$B$1,MATCH(#REF!,[1]Радиостанции!$B:$B,0)-1,3,COUNTIF([1]Радиостанции!$B:$B,#REF!),1)
Name OTSРадиоМосква: OFFSET([1]Радиостанции!$C$1,MATCH(Total_Москва!$E1,[1]Радиостанции!$C:$C,0)-1,3,COUNTIF([1]Радиостанции!$C:$C,Total_Москва!$E1),1)
Name OTSРадиоМосква: OFFSET([1]Радиостанции!$C$1,MATCH('Медиа факторы'!$N1,[1]Радиостанции!$C:$C,0)-1,3,COUNTIF([1]Радиостанции!$C:$C,'Медиа факторы'!$N1),1)
Name OTSРадиоМосква: OFFSET([2]Радиостанции!$C$1,MATCH(Москва!$P1,[2]Радиостанции!$C:$C,0)-1,3,COUNTIF([2]Радиостанции!$C:$C,Москва!$P1),1)
Name OTSРадиоМосква: OFFSET([1]Радиостанции!$C$1,MATCH(Фильтры!#REF!,[1]Радиостанции!$C:$C,0)-1,3,COUNTIF([1]Радиостанции!$C:$C,Фильтры!#REF!),1)
Name OTSРадиоМосква: OFFSET([1]Радиостанции!$C$1,MATCH(#REF!,[1]Радиостанции!$C:$C,0)-1,3,COUNTIF([1]Радиостанции!$C:$C,#REF!),1)
Name OTSТВ: OFFSET('[1]ТВ Каналы'!$B$1,MATCH(Total_Москва!#REF!,'[1]ТВ Каналы'!$B:$B,0)-1,4,COUNTIF('[1]ТВ Каналы'!$B:$B,Total_Москва!#REF!),1)
Name OTSТВ: OFFSET('[1]ТВ Каналы'!$B$1,MATCH('Медиа факторы'!$C1,'[1]ТВ Каналы'!$B:$B,0)-1,4,COUNTIF('[1]ТВ Каналы'!$B:$B,'Медиа факторы'!$C1),1)
Name OTSТВ: OFFSET('[2]ТВ Каналы'!$B$1,MATCH(Москва!$E1,'[2]ТВ Каналы'!$B:$B,0)-1,4,COUNTIF('[2]ТВ Каналы'!$B:$B,Москва!$E1),1)
Name OTSТВ: OFFSET('[1]ТВ Каналы'!$B$1,MATCH(Фильтры!$B1,'[1]ТВ Каналы'!$B:$B,0)-1,4,COUNTIF('[1]ТВ Каналы'!$B:$B,Фильтры!$B1),1)
Name OTSТВ: OFFSET('[1]ТВ Каналы'!$B$1,MATCH(#REF!,'[1]ТВ Каналы'!$B:$B,0)-1,4,COUNTIF('[1]ТВ Каналы'!$B:$B,#REF!),1)
Name OTSТВМосква: OFFSET('[1]ТВ Каналы'!$C$1,MATCH(Total_Москва!$E1,'[1]ТВ Каналы'!$C:$C,0)-1,3,COUNTIF('[1]ТВ Каналы'!$C:$C,Total_Москва!$E1),1)
Name OTSТВМосква: OFFSET('[1]ТВ Каналы'!$C$1,MATCH('Медиа факторы'!$N1,'[1]ТВ Каналы'!$C:$C,0)-1,3,COUNTIF('[1]ТВ Каналы'!$C:$C,'Медиа факторы'!$N1),1)
Name OTSТВМосква: OFFSET('[2]ТВ Каналы'!$C$1,MATCH(Москва!$P1,'[2]ТВ Каналы'!$C:$C,0)-1,3,COUNTIF('[2]ТВ Каналы'!$C:$C,Москва!$P1),1)
Name OTSТВМосква: OFFSET('[1]ТВ Каналы'!$C$1,MATCH(Фильтры!#REF!,'[1]ТВ Каналы'!$C:$C,0)-1,3,COUNTIF('[1]ТВ Каналы'!$C:$C,Фильтры!#REF!),1)
Name OTSТВМосква: OFFSET('[1]ТВ Каналы'!$C$1,MATCH(#REF!,'[1]ТВ Каналы'!$C:$C,0)-1,3,COUNTIF('[1]ТВ Каналы'!$C:$C,#REF!),1)
Name OTSТВСумм: SUM(Total_Москва!OTSТВ)
Name OTSТВСумм: SUM('Медиа факторы'!OTSТВ)
Name OTSТВСумм: SUM(Москва!OTSТВ)
Name OTSТВСумм: SUM(Фильтры!OTSТВ)
Name OTSТВСумм: SUM(OTSТВ)
Name Канал: OFFSET([1]ТВ!$A$1,MATCH(Total_Москва!#REF!,[1]ТВ!$A:$A,0)-1,1,COUNTIF([1]ТВ!$A:$A,Total_Москва!#REF!),1)
Name Канал: OFFSET([1]ТВ!$A$1,MATCH('Медиа факторы'!#REF!,[1]ТВ!$A:$A,0)-1,1,COUNTIF([1]ТВ!$A:$A,'Медиа факторы'!#REF!),1)
Name Канал: OFFSET([2]ТВ!$A$1,MATCH(Москва!$E$4,[2]ТВ!$A:$A,0)-1,1,COUNTIF([2]ТВ!$A:$A,Москва!$E$4),1)
Name Канал: OFFSET([1]ТВ!$A$1,MATCH(Фильтры!#REF!,[1]ТВ!$A:$A,0)-1,1,COUNTIF([1]ТВ!$A:$A,Фильтры!#REF!),1)
Name Канал: OFFSET([1]ТВ!$A$1,MATCH(#REF!,[1]ТВ!$A:$A,0)-1,1,COUNTIF([1]ТВ!$A:$A,#REF!),1)
Name МинутыРадио: OFFSET([1]Радиостанции!$B$1,MATCH(Total_Москва!#REF!,[1]Радиостанции!$B:$B,0)-1,2,COUNTIF([1]Радиостанции!$B:$B,Total_Москва!#REF!),1)
Name МинутыРадио: OFFSET([1]Радиостанции!$B$1,MATCH('Медиа факторы'!$C1,[1]Радиостанции!$B:$B,0)-1,2,COUNTIF([1]Радиостанции!$B:$B,'Медиа факторы'!$C1),1)
Name МинутыРадио: OFFSET([2]Радиостанции!$B$1,MATCH(Москва!$E1,[2]Радиостанции!$B:$B,0)-1,2,COUNTIF([2]Радиостанции!$B:$B,Москва!$E1),1)
Name МинутыРадио: OFFSET([1]Радиостанции!$B$1,MATCH(Фильтры!$B1,[1]Радиостанции!$B:$B,0)-1,2,COUNTIF([1]Радиостанции!$B:$B,Фильтры!$B1),1)
Name МинутыРадио: OFFSET([1]Радиостанции!$B$1,MATCH(#REF!,[1]Радиостанции!$B:$B,0)-1,2,COUNTIF([1]Радиостанции!$B:$B,#REF!),1)
Name МинутыРадиоМосква: OFFSET([1]Радиостанции!$C$1,MATCH(Total_Москва!$E1,[1]Радиостанции!$C:$C,0)-1,2,COUNTIF([1]Радиостанции!$C:$C,Total_Москва!$E1),1)
Name МинутыРадиоМосква: OFFSET([1]Радиостанции!$C$1,MATCH('Медиа факторы'!$N1,[1]Радиостанции!$C:$C,0)-1,2,COUNTIF([1]Радиостанции!$C:$C,'Медиа факторы'!$N1),1)
Name МинутыРадиоМосква: OFFSET([2]Радиостанции!$C$1,MATCH(Москва!$P1,[2]Радиостанции!$C:$C,0)-1,2,COUNTIF([2]Радиостанции!$C:$C,Москва!$P1),1)
Name МинутыРадиоМосква: OFFSET([1]Радиостанции!$C$1,MATCH(Фильтры!#REF!,[1]Радиостанции!$C:$C,0)-1,2,COUNTIF([1]Радиостанции!$C:$C,Фильтры!#REF!),1)
Name МинутыРадиоМосква: OFFSET([1]Радиостанции!$C$1,MATCH(#REF!,[1]Радиостанции!$C:$C,0)-1,2,COUNTIF([1]Радиостанции!$C:$C,#REF!),1)
Name МинутыТВ: OFFSET('[1]ТВ Каналы'!$B$1,MATCH(Total_Москва!#REF!,'[1]ТВ Каналы'!$B:$B,0)-1,2,COUNTIF('[1]ТВ Каналы'!$B:$B,Total_Москва!#REF!),1)
Name МинутыТВ: OFFSET('[1]ТВ Каналы'!$B$1,MATCH('Медиа факторы'!$C1,'[1]ТВ Каналы'!$B:$B,0)-1,2,COUNTIF('[1]ТВ Каналы'!$B:$B,'Медиа факторы'!$C1),1)
Name МинутыТВ: OFFSET('[2]ТВ Каналы'!$B$1,MATCH(Москва!$E1,'[2]ТВ Каналы'!$B:$B,0)-1,2,COUNTIF('[2]ТВ Каналы'!$B:$B,Москва!$E1),1)
Name МинутыТВ: OFFSET('[1]ТВ Каналы'!$B$1,MATCH(Фильтры!$B1,'[1]ТВ Каналы'!$B:$B,0)-1,2,COUNTIF('[1]ТВ Каналы'!$B:$B,Фильтры!$B1),1)
Name МинутыТВ: OFFSET('[1]ТВ Каналы'!$B$1,MATCH(#REF!,'[1]ТВ Каналы'!$B:$B,0)-1,2,COUNTIF('[1]ТВ Каналы'!$B:$B,#REF!),1)
Name МинутыТВМосква: OFFSET('[1]ТВ Каналы'!$C$1,MATCH(Total_Москва!$E1,'[1]ТВ Каналы'!$C:$C,0)-1,2,COUNTIF('[1]ТВ Каналы'!$C:$C,Total_Москва!$E1),1)
Name МинутыТВМосква: OFFSET('[1]ТВ Каналы'!$C$1,MATCH('Медиа факторы'!$N1,'[1]ТВ Каналы'!$C:$C,0)-1,2,COUNTIF('[1]ТВ Каналы'!$C:$C,'Медиа факторы'!$N1),1)
Name МинутыТВМосква: OFFSET('[2]ТВ Каналы'!$C$1,MATCH(Москва!$P1,'[2]ТВ Каналы'!$C:$C,0)-1,2,COUNTIF('[2]ТВ Каналы'!$C:$C,Москва!$P1),1)
Name МинутыТВМосква: OFFSET('[1]ТВ Каналы'!$C$1,MATCH(Фильтры!#REF!,'[1]ТВ Каналы'!$C:$C,0)-1,2,COUNTIF('[1]ТВ Каналы'!$C:$C,Фильтры!#REF!),1)
Name МинутыТВМосква: OFFSET('[1]ТВ Каналы'!$C$1,MATCH(#REF!,'[1]ТВ Каналы'!$C:$C,0)-1,2,COUNTIF('[1]ТВ Каналы'!$C:$C,#REF!),1)
Name Радио: OFFSET([1]Radio!$A$1,MATCH(Total_Москва!#REF!,[1]Radio!$A:$A,0)-1,1,COUNTIF([1]Radio!$A:$A,Total_Москва!#REF!),1)
Name Радио: OFFSET([1]Radio!$A$1,MATCH('Медиа факторы'!#REF!,[1]Radio!$A:$A,0)-1,1,COUNTIF([1]Radio!$A:$A,'Медиа факторы'!#REF!),1)
Name Радио: OFFSET([2]Radio!$A$1,MATCH(Москва!$E$4,[2]Radio!$A:$A,0)-1,1,COUNTIF([2]Radio!$A:$A,Москва!$E$4),1)
Name Радио: OFFSET([1]Radio!$A$1,MATCH(Фильтры!#REF!,[1]Radio!$A:$A,0)-1,1,COUNTIF([1]Radio!$A:$A,Фильтры!#REF!),1)
Name Радио: OFFSET([1]Radio!$A$1,MATCH(#REF!,[1]Radio!$A:$A,0)-1,1,COUNTIF([1]Radio!$A:$A,#REF!),1)

Sheet Медиа факторы
A1: Медиа факторы | B1: Описание | C1: Форматы | D1: Период размещения, дни | E1: Доля брендирования | F1: OTS 16+ ('000) | G1: Охват 16+* ('000) | H1: OTS 16+ ('000) (с учетом доли брендирования) | I1: Взаимодействие с контентом | J1: Характеристики инвентаря и аудитории | K1: Хронометраж | L1: Время взаимодействия с креативом | M1: Охват 16+ ('000) (с учетом доли брендирования)
A2: Тип активации: ДО МЕРОПРИЯТИЯ (медиа продвижение и PR) | B2: ООН | C2: BB | D2: 120 | E2: 0.3 | F2: 50000 | H2: 15000 | L2: 0 | M2: 1000
A3: Тип активации: ДО МЕРОПРИЯТИЯ (медиа продвижение и PR) | B3: Indoor | C3: Авиапарк | D3: 120 | E3: 0.3 | F3: 5000 | H3: 1500 | L3: 0 | M3: 300
A4: Тип активации: ДО МЕРОПРИЯТИЯ (медиа продвижение и PR) | B4: Радио | C4: Прямая Реклама | D4: 120 | E4: 0.2 | H4: 196668.21 | I4: 1076 | K4: 30 | L4: 15.84 | M4: 8304 | N4: =_xlfn.CONCAT(#REF!,C4) -> #REF!
A5: Тип активации: ДО МЕРОПРИЯТИЯ (медиа продвижение и PR) | B5: Digital | C5: Баннеры | D5: 120 | E5: 0.3 | F5: 24000 | H5: 7200 | L5: 0 | M5: 1440
A6: Тип активации: ДО МЕРОПРИЯТИЯ (медиа продвижение и PR) | B6: Digital | C6: Промо-пост | D6: 120 | E6: 0.3 | F6: 4000 | H6: 1200 | L6: 0 | M6: 240
A7: Тип активации: ДО МЕРОПРИЯТИЯ (медиа продвижение и PR) | B7: Айдентика Бренда партнера на сайте | C7: Billboard в шапке сайта | D7: 120 | E7: 1 | G7: 1100 | H7: 1100 | M7: 1100
A8: Тип активации: ДО МЕРОПРИЯТИЯ (медиа продвижение и PR) | B8: PR | C8: Статьи о событии | D8: 120 | E8: 0.5 | F8: 10000 | H8: 5000 | J8: 300 тыс | K8: 1 | M8: 3333.3333
A9: Тип активации: ПРОДВИЖЕНИЕ НА МЕРОПРИЯТИИ | B9: Видео | C9: Экраны на сцене | D9: 28 | E9: 1 | F9: 90 | H9: 90 | K9: 0 | M9: 30
A10: Тип активации: ПРОДВИЖЕНИЕ НА МЕРОПРИЯТИИ | B10: Брендирование | C10: брендинг вип-зоны | D10: 28 | E10: 1 | F10: 90 | H10: 90 | M10: 30
A11: Тип активации: ПРОДВИЖЕНИЕ НА МЕРОПРИЯТИИ | B11: Брендирование | C11: размещение арт-объекта | D11: 28 | E11: 1 | F11: 90 | H11: 90 | M11: 90
A12: Тип активации: ПРОДВИЖЕНИЕ НА МЕРОПРИЯТИИ | B12: Брендирование | C12: бренд-зона/лаундж-зона | D12: 28 | E12: 1 | F12: 90 | H12: 90 | M12: 60
A13: Тип активации: ПРОДВИЖЕНИЕ НА МЕРОПРИЯТИИ | B13: Брендирование | C13: брендинг браслетов | D13: 28 | E13: 1 | F13: 90 | H13: 90 | M13: 15
A14: Тип активации: ПРОДВИЖЕНИЕ НА МЕРОПРИЯТИИ | B14: Брендирование | C14: брендинг одежды персонала (бармены, гардеробщики) | D14: 28 | E14: 1 | F14: 90 | H14: 90 | M14: 45
A15: Тип активации: ПРОДВИЖЕНИЕ НА МЕРОПРИЯТИИ | B15: Брендирование | C15: брендированная раздатка (например, флешмоб с брендированными масками с лицом артиста) | D15: 28 | E15: 1 | F15: 90 | H15: 90 | M15: 30
A16: Тип активации: ПРОДВИЖЕНИЕ НА МЕРОПРИЯТИИ | B16: Брендирование | C16: брендированная зона раздачи мерча | D16: 28 | E16: 1 | F16: 90 | H16: 90 | M16: 90
A17: Тип активации: ПРОДВИЖЕНИЕ НА МЕРОПРИЯТИИ | B17: Брендирование | C17: AR-фотозона (с интерактивом) | D17: 28 | E17: 1 | F17: 90 | H17: 90 | M17: 45
A18: Тип активации: ПРОДВИЖЕНИЕ НА МЕРОПРИЯТИИ | B18: Брендирование | C18: флаги/штендеры/лайтбоксы/расклеенные печатные лого/тейбл-тенты на локации мероприятия | D18: 28 | E18: 1 | F18: 90 | H18: 90 | M18: 60
A19: Тип активации: ПРОДВИЖЕНИЕ НА МЕРОПРИЯТИИ | B19: Брендирование | C19: раздача/продажа брендированного мерча на площадке | D19: 28 | E19: 1 | F19: 90 | H19: 90 | M19: 90
A20: Тип активации: ПРОДВИЖЕНИЕ НА МЕРОПРИЯТИИ | B20: Промо-акции | C20: Различные акции с участием промо-персонала | D20: 28 | E20: 1 | F20: 90 | H20: 90 | M20: 60
A21: Тип активации: ДОПОЛНИТЕЛЬНЫЕ АКТИВАЦИИ ПОСЛЕ МЕРОПРИЯТИЯ | B21: Лого партнера | C21: Интеграция в фото и видео отчеты | H21: - | I21: 6 | K21: 1 | M21: 0
A22: Тип активации: ДОПОЛНИТЕЛЬНЫЕ АКТИВАЦИИ ПОСЛЕ МЕРОПРИЯТИЯ | B22: Лого партнера | C22: PR публикации | H22: - | I22: 8 | K22: 1 | M22: 0
A23: Тип активации: ДОПОЛНИТЕЛЬНЫЕ АКТИВАЦИИ ПОСЛЕ МЕРОПРИЯТИЯ | B23: Лого партнера | C23: Интеграция в посты у артиста | H23: - | I23: 7 | K23: 1 | M23: 0

Sheet Фильтры
A1: Блок | B1: Название | C1: Данные
A2: ПЛАНОВЫЙ РЕЗУЛЬТАТ МЕРОПРИЯТИЯ | B2: Кол-во посетителей всего, тыс. | C2: 90
A3: ПЛАНОВЫЙ РЕЗУЛЬТАТ МЕРОПРИЯТИЯ | B3: Средняя цена билета
A4: ПЛАНОВЫЙ РЕЗУЛЬТАТ МЕРОПРИЯТИЯ | B4: GMV
A5: ПЛАНОВЫЙ РЕЗУЛЬТАТ МЕРОПРИЯТИЯ | B5: Агентская комиссия
A6: ПЛАНОВЫЙ РЕЗУЛЬТАТ МЕРОПРИЯТИЯ | B6: Количество проданных билетов через виджит/витрину
A7: БЮДЖЕТ | B7: Интеграционный платеж (организатору) | C7: 5000000
A8: БЮДЖЕТ | B8: Продакшен фото-зоны и лайтбокса, букингсекретных артистов | C8: 19763161
A9: БЮДЖЕТ | B9: Общий бюджет | C9: =SUM(C7:C8) -> 24763161
A10: ЭФФЕКТИВНОСТЬ | B10: Стоимость привлеченного клиента
A11: ЭФФЕКТИВНОСТЬ | B11: Стоимость за контакт | C11: 0.1082551
A12: ЭФФЕКТИВНОСТЬ | B12: Стоимость за охваченного пользователя | C12: 3.9999062
A13: ЭФФЕКТИВНОСТЬ | B13: Стоимость за посетителя мероприятия | C13: 275.14623
A14: ПАРАМЕТРЫ | B14: ЦА (унифицированная аудитория для всех медиа, тыс. 16+) | C14: 11062.57
A15: ПАРАМЕТРЫ | B15: количество дней на фестивале/площадке | C15: 28
A16: ПАРАМЕТРЫ | B16: Общий период размещения | C16: 120
A17: ПАРАМЕТРЫ | B17: План посетителей (в тыс. человек) | C17: 90

Sheet Total_Москва
A1: Медиа факторы | B1: Описание | C1: OTS 16+ ('000) (с учетом доли брендирования) | D1: Охват 16+ ('000) (с учетом доли брендирования)
A2: Тип активации: ДО МЕРОПРИЯТИЯ (медиа продвижение и PR) | B2: ООН | C2: 15000 | D2: 1000
A3: Тип активации: ДО МЕРОПРИЯТИЯ (медиа продвижение и PR) | B3: Indoor | C3: 1500 | D3: 300
A4: Тип активации: ДО МЕРОПРИЯТИЯ (медиа продвижение и PR) | B4: Радио | C4: 196668.21 | D4: 8303.7687
A5: Тип активации: ДО МЕРОПРИЯТИЯ (медиа продвижение и PR) | B5: Digital | C5: 8400 | D5: 1440
A6: Тип активации: ДО МЕРОПРИЯТИЯ (медиа продвижение и PR) | B6: Айдентика Бренда партнера на сайте | C6: 1100 | D6: 1100
A7: Тип активации: ДО МЕРОПРИЯТИЯ (медиа продвижение и PR) | B7: PR | C7: 5000 | D7: 3333.3333
A8: Тип активации: ПРОДВИЖЕНИЕ НА МЕРОПРИЯТИИ | B8: Видео | C8: 90 | D8: 30
A9: Тип активации: ПРОДВИЖЕНИЕ НА МЕРОПРИЯТИИ | B9: Брендирование | C9: 900 | D9: 90
A10: Тип активации: ПРОДВИЖЕНИЕ НА МЕРОПРИЯТИИ | B10: Промо-акции | C10: 90 | D10: 60
A11: Тип активации: ПРОДВИЖЕНИЕ НА МЕРОПРИЯТИИ | B11: Взаимодействие с артистом во время мероприятия
A12: Тип активации: ПРОДВИЖЕНИЕ НА МЕРОПРИЯТИИ | B12: UGC
A13: Тип активации: ДОПОЛНИТЕЛЬНЫЕ АКТИВАЦИИ ПОСЛЕ МЕРОПРИЯТИЯ | B13: Лого партнера
A14: Итог | C14: 228748.21 | D14: 6190.9354

Sheet Москва
C2: Параметры | D2: Описание
C3: ЦА | D3: Унифицированная аудитория для всех медиа, тыс. 16+ | E3: 11062.57
B4: 1 | C4: Гео | D4: 15 городов | E4: Москва
C5: Тип площадки | D5: концерт/фестиваль/площадка | E5: Площадка
D6: количество дней на фестивале/площадке | E6: 28
B7: 2 | C7: Общий период размещения | D7: в днях | E7: 120
B8: 3 | C8: План посетителей | D8: в тысячах человек | E8: 90
B9: # | C9: Медиа факторы | D9: Описание | E9: Форматы | F9: Период размещения, дни | G9: Доля брендирования | H9: OTS 16+ ('000) | I9: Охват 16+* ('000) | J9: OTS 16+ ('000) (с учетом доли брендирования) | K9: Как оцениваем OTS медиа, в случае отсутствия данных по OTS и Охватам у поставщика | M9: Индекс качества (для медиа) | O9: Охват 16+ ('000) (с учетом доли брендирования)
B10: 4 | C10: Тип активации: ДО МЕРОПРИЯТИЯ (медиа продвижение и PR) | D10: ТВ | J10: =SUM(J11:J12) -> 0 | K10: Количество минут в день | L10: Каналы | M10: Хронометраж | N10: Время взаимодействия с креативом | O10: =IFERROR(IF(J10>0,J10/VLOOKUP(D10,'[2]Коэфы качество контакта'!$A$2:$G$22,7,FALSE),(1-(1-(O11/$E$3*0.5))*(1-(O12/$E$3*0.5)))*$E$3),0) -> 0
D11: ТВ | E11: Спонсорство | J11: {=IFERROR(IF(H11>0,H11*G11,IF(K11>0,SUM(OTSТВМосква)*G11*F11*(K11/200),IF(I11>0,G11*I11*SUMPRODUCT(('[2]Коэфы качество контакта'!$A$2:$A$50=D11)*'[2]Коэфы качество контакта'!$G$2:$G$50),""))),"")} | K11: =IFERROR(SUM(МинутыТВМосква),0) -> 0 | L11: Каналы из списка | N11: =M11*VLOOKUP(D11,'[2]Коэфы качество контакта'!$A$2:$E$22,3,FALSE)*VLOOKUP(D11,'[2]Коэфы качество контакта'!$A$2:$E$22,5,FALSE) -> 0 | O11: =IFERROR(IF(I11>0,I11*G11,J11/VLOOKUP(D11,'[2]Коэфы качество контакта'!$A$2:$G$22,7,FALSE)),"") | P11: =_xlfn.CONCAT($E$4,E11) -> МоскваСпонсорство
D12: ТВ | E12: Прямая Реклама | J12: {=IFERROR(IF(H12>0,H12*G12,IF(K12>0,SUM(OTSТВМосква)*G12*F12*(K12/200),IF(I12>0,G12*I12*SUMPRODUCT(('[2]Коэфы качество контакта'!$A$2:$A$50=D12)*'[2]Коэфы качество контакта'!$G$2:$G$50),""))),"")} | K12: =IFERROR(SUM(МинутыТВМосква),0) -> 0 | L12: Каналы из списка | N12: =M12*VLOOKUP(D12,'[2]Коэфы качество контакта'!$A$2:$E$22,3,FALSE)*VLOOKUP(D12,'[2]Коэфы качество контакта'!$A$2:$E$22,5,FALSE) -> 0 | O12: =IFERROR(IF(I12>0,I12*G12,J12/VLOOKUP(D12,'[2]Коэфы качество контакта'!$A$2:$G$22,7,FALSE)),"") | P12: =_xlfn.CONCAT($E$4,E12) -> МоскваПрямая Реклама
D13: ООН | J13: =SUM(J14:J21) -> 15000 | K13: Количество сторон | M13: Хронометраж | N13: Время взаимодействия с креативом | O13: =IFERROR(IF(J13>0,J13/VLOOKUP(D13,'[2]Коэфы качество контакта'!$A$2:$G$22,7,FALSE),(1-(1-(O14/$E$3*0.5))*(1-(O15/$E$3*0.5))*(1-(O16/$E$3*0.5))*(1-(O17/$E$3*0.5))*(1-(O18/$E$3*0.5))*(1-(O19/$E$3*0.5))*(1-(O20/$E$3*0.5))*(1-(O21/$E$3*0.5)))*$E$3),) -> 1000
D14: ООН | E14: BB | F14: 120 | G14: 0.3 | H14: 50000 | J14: {=IF(H14>0,H14*G14,IF(K14>0,SUMPRODUCT(([2]OOH!$A$2:$A$1000=Москва!$E$4)*([2]OOH!$B$2:$B$1000=Москва!$E14)*[2]OOH!$C$2:$C$1000)*F14*K14*G14,IF(I14>0,G14*I14*SUMPRODUCT(('[2]Коэфы качество контакта'!$A$2:$A$50=D14)*'[2]Коэфы качество контакта'!$G$2:$G$50),"")))} -> 15000 | N14: =M14*VLOOKUP(D14,'[2]Коэфы качество контакта'!$A$2:$E$22,3,FALSE)*VLOOKUP(D14,'[2]Коэфы качество контакта'!$A$2:$E$22,5,FALSE) -> 0 | O14: =IFERROR(IF(I14>0,I14*G14,J14/VLOOKUP(D14,'[2]Коэфы качество контакта'!$A$2:$G$22,7,FALSE)),"") -> 1000
D15: ООН | E15: DBB | J15: {=IF(H15>0,H15*G15,IF(K15>0,SUMPRODUCT(([2]OOH!$A$2:$A$1000=Москва!$E$4)*([2]OOH!$B$2:$B$1000=Москва!$E15)*[2]OOH!$C$2:$C$1000)*F15*K15*G15,IF(I15>0,G15*I15*SUMPRODUCT(('[2]Коэфы качество контакта'!$A$2:$A$50=D15)*'[2]Коэфы качество контакта'!$G$2:$G$50),"")))} | N15: =M15*VLOOKUP(D15,'[2]Коэфы качество контакта'!$A$2:$E$22,3,FALSE)*VLOOKUP(D15,'[2]Коэфы качество контакта'!$A$2:$E$22,5,FALSE) -> 0 | O15: =IFERROR(IF(I15>0,I15*G15,J15/VLOOKUP(D15,'[2]Коэфы качество контакта'!$A$2:$G$22,7,FALSE)),"")
D16: ООН | E16: PL | J16: {=IF(H16>0,H16*G16,IF(K16>0,SUMPRODUCT(([2]OOH!$A$2:$A$1000=Москва!$E$4)*([2]OOH!$B$2:$B$1000=Москва!$E16)*[2]OOH!$C$2:$C$1000)*F16*K16*G16,IF(I16>0,G16*I16*SUMPRODUCT(('[2]Коэфы качество контакта'!$A$2:$A$50=D16)*'[2]Коэфы качество контакта'!$G$2:$G$50),"")))} | N16: =M16*VLOOKUP(D16,'[2]Коэфы качество контакта'!$A$2:$E$22,3,FALSE)*VLOOKUP(D16,'[2]Коэфы качество контакта'!$A$2:$E$22,5,FALSE) -> 0 | O16: =IFERROR(IF(I16>0,I16*G16,J16/VLOOKUP(D16,'[2]Коэфы качество контакта'!$A$2:$G$22,7,FALSE)),"")
D17: ООН | E17: SS | J17: {=IF(H17>0,H17*G17,IF(K17>0,SUMPRODUCT(([2]OOH!$A$2:$A$1000=Москва!$E$4)*([2]OOH!$B$2:$B$1000=Москва!$E17)*[2]OOH!$C$2:$C$1000)*F17*K17*G17,IF(I17>0,G17*I17*SUMPRODUCT(('[2]Коэфы качество контакта'!$A$2:$A$50=D17)*'[2]Коэфы качество контакта'!$G$2:$G$50),"")))} | N17: =M17*VLOOKUP(D17,'[2]Коэфы качество контакта'!$A$2:$E$22,3,FALSE)*VLOOKUP(D17,'[2]Коэфы качество контакта'!$A$2:$E$22,5,FALSE) -> 0 | O17: =IFERROR(IF(I17>0,I17*G17,J17/VLOOKUP(D17,'[2]Коэфы качество контакта'!$A$2:$G$22,7,FALSE)),"")
D18: ООН | E18: CF | J18: {=IF(H18>0,H18*G18,IF(K18>0,SUMPRODUCT(([2]OOH!$A$2:$A$1000=Москва!$E$4)*([2]OOH!$B$2:$B$1000=Москва!$E18)*[2]OOH!$C$2:$C$1000)*F18*K18*G18,IF(I18>0,G18*I18*SUMPRODUCT(('[2]Коэфы качество контакта'!$A$2:$A$50=D18)*'[2]Коэфы качество контакта'!$G$2:$G$50),"")))} | N18: =M18*VLOOKUP(D18,'[2]Коэфы качество контакта'!$A$2:$E$22,3,FALSE)*VLOOKUP(D18,'[2]Коэфы качество контакта'!$A$2:$E$22,5,FALSE) -> 0 | O18: =IFERROR(IF(I18>0,I18*G18,J18/VLOOKUP(D18,'[2]Коэфы качество контакта'!$A$2:$G$22,7,FALSE)),"")
D19: ООН | J19: {=IF(H19>0,H19*G19,IF(K19>0,SUMPRODUCT(([2]OOH!$A$2:$A$1000=Москва!$E$4)*([2]OOH!$B$2:$B$1000=Москва!$E19)*[2]OOH!$C$2:$C$1000)*F19*K19*G19,IF(I19>0,G19*I19*SUMPRODUCT(('[2]Коэфы качество контакта'!$A$2:$A$50=D19)*'[2]Коэфы качество контакта'!$G$2:$G$50),"")))} | N19: =M19*VLOOKUP(D19,'[2]Коэфы качество контакта'!$A$2:$E$22,3,FALSE)*VLOOKUP(D19,'[2]Коэфы качество контакта'!$A$2:$E$22,5,FALSE) -> 0 | O19: =IFERROR(IF(I19>0,I19*G19,J19/VLOOKUP(D19,'[2]Коэфы качество контакта'!$A$2:$G$22,7,FALSE)),"")
D20: ООН | J20: {=IF(H20>0,H20*G20,IF(K20>0,SUMPRODUCT(([2]OOH!$A$2:$A$1000=Москва!$E$4)*([2]OOH!$B$2:$B$1000=Москва!$E20)*[2]OOH!$C$2:$C$1000)*F20*K20*G20,IF(I20>0,G20*I20*SUMPRODUCT(('[2]Коэфы качество контакта'!$A$2:$A$50=D20)*'[2]Коэфы качество контакта'!$G$2:$G$50),"")))} | N20: =M20*VLOOKUP(D20,'[2]Коэфы качество контакта'!$A$2:$E$22,3,FALSE)*VLOOKUP(D20,'[2]Коэфы качество контакта'!$A$2:$E$22,5,FALSE) -> 0 | O20: =IFERROR(IF(I20>0,I20*G20,J20/VLOOKUP(D20,'[2]Коэфы качество контакта'!$A$2:$G$22,7,FALSE)),"")
D21: ООН | J21: {=IF(H21>0,H21*G21,IF(K21>0,SUMPRODUCT(([2]OOH!$A$2:$A$1000=Москва!$E$4)*([2]OOH!$B$2:$B$1000=Москва!$E21)*[2]OOH!$C$2:$C$1000)*F21*K21*G21,IF(I21>0,G21*I21*SUMPRODUCT(('[2]Коэфы качество контакта'!$A$2:$A$50=D21)*'[2]Коэфы качество контакта'!$G$2:$G$50),"")))} | L21: - | N21: =M21*VLOOKUP(D21,'[2]Коэфы качество контакта'!$A$2:$E$22,3,FALSE)*VLOOKUP(D21,'[2]Коэфы качество контакта'!$A$2:$E$22,5,FALSE) -> 0 | O21: =IFERROR(IF(I21>0,I21*G21,J21/VLOOKUP(D21,'[2]Коэфы качество контакта'!$A$2:$G$22,7,FALSE)),"")
D22: Indoor | J22: =SUM(J23:J42) -> 1500 | M22: Хронометраж | N22: Время взаимодействия с креативом | O22: =IF(J22>0,J22/VLOOKUP(D22,'[2]Коэфы качество контакта'!$A$2:$G$22,7,FALSE),(1-(1-(O23/$E$3*0.5))*(1-(O24/$E$3*0.5))*(1-(O25/$E$3*0.5))*(1-(O26/$E$3*0.5))*(1-(O27/$E$3*0.5))*(1-(O28/$E$3*0.5))*(1-(O29/$E$3*0.5))*(1-(O30/$E$3*0.5))*(1-(O31/$E$3*0.5))*(1-(O32/$E$3*0.5))*(1-(O33/$E$3*0.5))*(1-(O34/$E$3*0.5))*(1-(O35/$E$3*0.5))*(1-(O36/$E$3*0.5))*(1-(O37/$E$3*0.5))*(1-(O38/$E$3*0.5))*(1-(O39/$E$3*0.5))*(1-(O40/$E$3*0.5))*(1-(O41/$E$3*0.5))*(1-(O42/$E$3*0.5)))*$E$3) -> 300
D23: Indoor | E23: Авиапарк | F23: 120 | G23: 0.3 | H23: 5000 | J23: {=IF(H23>0,H23*G23,IF(I23>0,G23*I23*SUMPRODUCT(('[2]Коэфы качество контакта'!$A$2:$A$50=D23)*'[2]Коэфы качество контакта'!$G$2:$G$50),SUMPRODUCT(([2]Indoor!$A$2:$A$996=Москва!$E$4)*([2]Indoor!$B$2:$B$996=Москва!$E23)*[2]Indoor!$F$2:$F$996)*F23*G23))} -> 1500 | N23: =M23*VLOOKUP(D23,'[2]Коэфы качество контакта'!$A$2:$E$22,3,FALSE)*VLOOKUP(D23,'[2]Коэфы качество контакта'!$A$2:$E$22,5,FALSE) -> 0 | O23: {=IFERROR(IF(I23>0,I23*G23,J23/SUMPRODUCT(([2]Indoor!$A$2:$A$996=Москва!$E$4)*([2]Indoor!$B$2:$B$996=Москва!$E23)*[2]Indoor!$G$2:$G$996)),0)} -> 300
D24: Indoor | E24: ТЦ Атриум | J24: {=IF(H24>0,H24*G24,IF(I24>0,G24*I24*SUMPRODUCT(('[2]Коэфы качество контакта'!$A$2:$A$50=D24)*'[2]Коэфы качество контакта'!$G$2:$G$50),SUMPRODUCT(([2]Indoor!$A$2:$A$996=Москва!$E$4)*([2]Indoor!$B$2:$B$996=Москва!$E24)*[2]Indoor!$F$2:$F$996)*F24*G24))} -> 0 | N24: =M24*VLOOKUP(D24,'[2]Коэфы качество контакта'!$A$2:$E$22,3,FALSE)*VLOOKUP(D24,'[2]Коэфы качество контакта'!$A$2:$E$22,5,FALSE) -> 0 | O24: {=IFERROR(IF(I24>0,I24*G24,J24/SUMPRODUCT(([2]Indoor!$A$2:$A$996=Москва!$E$4)*([2]Indoor!$B$2:$B$996=Москва!$E24)*[2]Indoor!$G$2:$G$996)),0)} -> 0
D25: Indoor | E25: ПВЗ | J25: {=IF(H25>0,H25*G25,IF(I25>0,G25*I25*SUMPRODUCT(('[2]Коэфы качество контакта'!$A$2:$A$50=D25)*'[2]Коэфы качество контакта'!$G$2:$G$50),SUMPRODUCT(([2]Indoor!$A$2:$A$996=Москва!$E$4)*([2]Indoor!$B$2:$B$996=Москва!$E25)*[2]Indoor!$F$2:$F$996)*F25*G25))} -> 0 | N25: =M25*VLOOKUP(D25,'[2]Коэфы качество контакта'!$A$2:$E$22,3,FALSE)*VLOOKUP(D25,'[2]Коэфы качество контакта'!$A$2:$E$22,5,FALSE) -> 0 | O25: {=IFERROR(IF(I25>0,I25*G25,J25/SUMPRODUCT(([2]Indoor!$A$2:$A$996=Москва!$E$4)*([2]Indoor!$B$2:$B$996=Москва!$E25)*[2]Indoor!$G$2:$G$996)),0)} -> 0
D26: Indoor | E26: ТЦ Коламбус | J26: {=IF(H26>0,H26*G26,IF(I26>0,G26*I26*SUMPRODUCT(('[2]Коэфы качество контакта'!$A$2:$A$50=D26)*'[2]Коэфы качество контакта'!$G$2:$G$50),SUMPRODUCT(([2]Indoor!$A$2:$A$996=Москва!$E$4)*([2]Indoor!$B$2:$B$996=Москва!$E26)*[2]Indoor!$F$2:$F$996)*F26*G26))} -> 0 | N26: =M26*VLOOKUP(D26,'[2]Коэфы качество контакта'!$A$2:$E$22,3,FALSE)*VLOOKUP(D26,'[2]Коэфы качество контакта'!$A$2:$E$22,5,FALSE) -> 0 | O26: {=IFERROR(IF(I26>0,I26*G26,J26/SUMPRODUCT(([2]Indoor!$A$2:$A$996=Москва!$E$4)*([2]Indoor!$B$2:$B$996=Москва!$E26)*[2]Indoor!$G$2:$G$996)),0)} -> 0
D27: Indoor | J27: {=IF(H27>0,H27*G27,IF(I27>0,G27*I27*SUMPRODUCT(('[2]Коэфы качество контакта'!$A$2:$A$50=D27)*'[2]Коэфы качество контакта'!$G$2:$G$50),SUMPRODUCT(([2]Indoor!$A$2:$A$996=Москва!$E$4)*([2]Indoor!$B$2:$B$996=Москва!$E27)*[2]Indoor!$F$2:$F$996)*F27*G27))} -> 0 | N27: =M27*VLOOKUP(D27,'[2]Коэфы качество контакта'!$A$2:$E$22,3,FALSE)*VLOOKUP(D27,'[2]Коэфы качество контакта'!$A$2:$E$22,5,FALSE) -> 0 | O27: {=IFERROR(IF(I27>0,I27*G27,J27/SUMPRODUCT(([2]Indoor!$A$2:$A$996=Москва!$E$4)*([2]Indoor!$B$2:$B$996=Москва!$E27)*[2]Indoor!$G$2:$G$996)),0)} -> 0
D28: Indoor | J28: {=IF(H28>0,H28*G28,IF(I28>0,G28*I28*SUMPRODUCT(('[2]Коэфы качество контакта'!$A$2:$A$50=D28)*'[2]Коэфы качество контакта'!$G$2:$G$50),SUMPRODUCT(([2]Indoor!$A$2:$A$996=Москва!$E$4)*([2]Indoor!$B$2:$B$996=Москва!$E28)*[2]Indoor!$F$2:$F$996)*F28*G28))} -> 0 | N28: =M28*VLOOKUP(D28,'[2]Коэфы качество контакта'!$A$2:$E$22,3,FALSE)*VLOOKUP(D28,'[2]Коэфы качество контакта'!$A$2:$E$22,5,FALSE) -> 0 | O28: {=IFERROR(IF(I28>0,I28*G28,J28/SUMPRODUCT(([2]Indoor!$A$2:$A$996=Москва!$E$4)*([2]Indoor!$B$2:$B$996=Москва!$E28)*[2]Indoor!$G$2:$G$996)),0)} -> 0
D29: Indoor | J29: {=IF(H29>0,H29*G29,IF(I29>0,G29*I29*SUMPRODUCT(('[2]Коэфы качество контакта'!$A$2:$A$50=D29)*'[2]Коэфы качество контакта'!$G$2:$G$50),SUMPRODUCT(([2]Indoor!$A$2:$A$996=Москва!$E$4)*([2]Indoor!$B$2:$B$996=Москва!$E29)*[2]Indoor!$F$2:$F$996)*F29*G29))} -> 0 | N29: =M29*VLOOKUP(D29,'[2]Коэфы качество контакта'!$A$2:$E$22,3,FALSE)*VLOOKUP(D29,'[2]Коэфы качество контакта'!$A$2:$E$22,5,FALSE) -> 0 | O29: {=IFERROR(IF(I29>0,I29*G29,J29/SUMPRODUCT(([2]Indoor!$A$2:$A$996=Москва!$E$4)*([2]Indoor!$B$2:$B$996=Москва!$E29)*[2]Indoor!$G$2:$G$996)),0)} -> 0
D30: Indoor | J30: {=IF(H30>0,H30*G30,IF(I30>0,G30*I30*SUMPRODUCT(('[2]Коэфы качество контакта'!$A$2:$A$50=D30)*'[2]Коэфы качество контакта'!$G$2:$G$50),SUMPRODUCT(([2]Indoor!$A$2:$A$996=Москва!$E$4)*([2]Indoor!$B$2:$B$996=Москва!$E30)*[2]Indoor!$F$2:$F$996)*F30*G30))} -> 0 | N30: =M30*VLOOKUP(D30,'[2]Коэфы качество контакта'!$A$2:$E$22,3,FALSE)*VLOOKUP(D30,'[2]Коэфы качество контакта'!$A$2:$E$22,5,FALSE) -> 0 | O30: {=IFERROR(IF(I30>0,I30*G30,J30/SUMPRODUCT(([2]Indoor!$A$2:$A$996=Москва!$E$4)*([2]Indoor!$B$2:$B$996=Москва!$E30)*[2]Indoor!$G$2:$G$996)),0)} -> 0
D31: Indoor | J31: {=IF(H31>0,H31*G31,IF(I31>0,G31*I31*SUMPRODUCT(('[2]Коэфы качество контакта'!$A$2:$A$50=D31)*'[2]Коэфы качество контакта'!$G$2:$G$50),SUMPRODUCT(([2]Indoor!$A$2:$A$996=Москва!$E$4)*([2]Indoor!$B$2:$B$996=Москва!$E31)*[2]Indoor!$F$2:$F$996)*F31*G31))} -> 0 | N31: =M31*VLOOKUP(D31,'[2]Коэфы качество контакта'!$A$2:$E$22,3,FALSE)*VLOOKUP(D31,'[2]Коэфы качество контакта'!$A$2:$E$22,5,FALSE) -> 0 | O31: {=IFERROR(IF(I31>0,I31*G31,J31/SUMPRODUCT(([2]Indoor!$A$2:$A$996=Москва!$E$4)*([2]Indoor!$B$2:$B$996=Москва!$E31)*[2]Indoor!$G$2:$G$996)),0)} -> 0
D32: Indoor | J32: {=IF(H32>0,H32*G32,IF(I32>0,G32*I32*SUMPRODUCT(('[2]Коэфы качество контакта'!$A$2:$A$50=D32)*'[2]Коэфы качество контакта'!$G$2:$G$50),SUMPRODUCT(([2]Indoor!$A$2:$A$996=Москва!$E$4)*([2]Indoor!$B$2:$B$996=Москва!$E32)*[2]Indoor!$F$2:$F$996)*F32*G32))} -> 0 | N32: =M32*VLOOKUP(D32,'[2]Коэфы качество контакта'!$A$2:$E$22,3,FALSE)*VLOOKUP(D32,'[2]Коэфы качество контакта'!$A$2:$E$22,5,FALSE) -> 0 | O32: {=IFERROR(IF(I32>0,I32*G32,J32/SUMPRODUCT(([2]Indoor!$A$2:$A$996=Москва!$E$4)*([2]Indoor!$B$2:$B$996=Москва!$E32)*[2]Indoor!$G$2:$G$996)),0)} -> 0
D33: Indoor | J33: {=IF(H33>0,H33*G33,IF(I33>0,G33*I33*SUMPRODUCT(('[2]Коэфы качество контакта'!$A$2:$A$50=D33)*'[2]Коэфы качество контакта'!$G$2:$G$50),SUMPRODUCT(([2]Indoor!$A$2:$A$996=Москва!$E$4)*([2]Indoor!$B$2:$B$996=Москва!$E33)*[2]Indoor!$F$2:$F$996)*F33*G33))} -> 0 | N33: =M33*VLOOKUP(D33,'[2]Коэфы качество контакта'!$A$2:$E$22,3,FALSE)*VLOOKUP(D33,'[2]Коэфы качество контакта'!$A$2:$E$22,5,FALSE) -> 0 | O33: {=IFERROR(IF(I33>0,I33*G33,J33/SUMPRODUCT(([2]Indoor!$A$2:$A$996=Москва!$E$4)*([2]Indoor!$B$2:$B$996=Москва!$E33)*[2]Indoor!$G$2:$G$996)),0)} -> 0
D34: Indoor | J34: {=IF(H34>0,H34*G34,IF(I34>0,G34*I34*SUMPRODUCT(('[2]Коэфы качество контакта'!$A$2:$A$50=D34)*'[2]Коэфы качество контакта'!$G$2:$G$50),SUMPRODUCT(([2]Indoor!$A$2:$A$996=Москва!$E$4)*([2]Indoor!$B$2:$B$996=Москва!$E34)*[2]Indoor!$F$2:$F$996)*F34*G34))} -> 0 | N34: =M34*VLOOKUP(D34,'[2]Коэфы качество контакта'!$A$2:$E$22,3,FALSE)*VLOOKUP(D34,'[2]Коэфы качество контакта'!$A$2:$E$22,5,FALSE) -> 0 | O34: {=IFERROR(IF(I34>0,I34*G34,J34/SUMPRODUCT(([2]Indoor!$A$2:$A$996=Москва!$E$4)*([2]Indoor!$B$2:$B$996=Москва!$E34)*[2]Indoor!$G$2:$G$996)),0)} -> 0
D35: Indoor | J35: {=IF(H35>0,H35*G35,IF(I35>0,G35*I35*SUMPRODUCT(('[2]Коэфы качество контакта'!$A$2:$A$50=D35)*'[2]Коэфы качество контакта'!$G$2:$G$50),SUMPRODUCT(([2]Indoor!$A$2:$A$996=Москва!$E$4)*([2]Indoor!$B$2:$B$996=Москва!$E35)*[2]Indoor!$F$2:$F$996)*F35*G35))} -> 0 | N35: =M35*VLOOKUP(D35,'[2]Коэфы качество контакта'!$A$2:$E$22,3,FALSE)*VLOOKUP(D35,'[2]Коэфы качество контакта'!$A$2:$E$22,5,FALSE) -> 0 | O35: {=IFERROR(IF(I35>0,I35*G35,J35/SUMPRODUCT(([2]Indoor!$A$2:$A$996=Москва!$E$4)*([2]Indoor!$B$2:$B$996=Москва!$E35)*[2]Indoor!$G$2:$G$996)),0)} -> 0
D36: Indoor | J36: {=IF(H36>0,H36*G36,IF(I36>0,G36*I36*SUMPRODUCT(('[2]Коэфы качество контакта'!$A$2:$A$50=D36)*'[2]Коэфы качество контакта'!$G$2:$G$50),SUMPRODUCT(([2]Indoor!$A$2:$A$996=Москва!$E$4)*([2]Indoor!$B$2:$B$996=Москва!$E36)*[2]Indoor!$F$2:$F$996)*F36*G36))} -> 0 | N36: =M36*VLOOKUP(D36,'[2]Коэфы качество контакта'!$A$2:$E$22,3,FALSE)*VLOOKUP(D36,'[2]Коэфы качество контакта'!$A$2:$E$22,5,FALSE) -> 0 | O36: {=IFERROR(IF(I36>0,I36*G36,J36/SUMPRODUCT(([2]Indoor!$A$2:$A$996=Москва!$E$4)*([2]Indoor!$B$2:$B$996=Москва!$E36)*[2]Indoor!$G$2:$G$996)),0)} -> 0
D37: Indoor | J37: {=IF(H37>0,H37*G37,IF(I37>0,G37*I37*SUMPRODUCT(('[2]Коэфы качество контакта'!$A$2:$A$50=D37)*'[2]Коэфы качество контакта'!$G$2:$G$50),SUMPRODUCT(([2]Indoor!$A$2:$A$996=Москва!$E$4)*([2]Indoor!$B$2:$B$996=Москва!$E37)*[2]Indoor!$F$2:$F$996)*F37*G37))} -> 0 | N37: =M37*VLOOKUP(D37,'[2]Коэфы качество контакта'!$A$2:$E$22,3,FALSE)*VLOOKUP(D37,'[2]Коэфы качество контакта'!$A$2:$E$22,5,FALSE) -> 0 | O37: {=IFERROR(IF(I37>0,I37*G37,J37/SUMPRODUCT(([2]Indoor!$A$2:$A$996=Москва!$E$4)*([2]Indoor!$B$2:$B$996=Москва!$E37)*[2]Indoor!$G$2:$G$996)),0)} -> 0
D38: Indoor | J38: {=IF(H38>0,H38*G38,IF(I38>0,G38*I38*SUMPRODUCT(('[2]Коэфы качество контакта'!$A$2:$A$50=D38)*'[2]Коэфы качество контакта'!$G$2:$G$50),SUMPRODUCT(([2]Indoor!$A$2:$A$996=Москва!$E$4)*([2]Indoor!$B$2:$B$996=Москва!$E38)*[2]Indoor!$F$2:$F$996)*F38*G38))} -> 0 | N38: =M38*VLOOKUP(D38,'[2]Коэфы качество контакта'!$A$2:$E$22,3,FALSE)*VLOOKUP(D38,'[2]Коэфы качество контакта'!$A$2:$E$22,5,FALSE) -> 0 | O38: {=IFERROR(IF(I38>0,I38*G38,J38/SUMPRODUCT(([2]Indoor!$A$2:$A$996=Москва!$E$4)*([2]Indoor!$B$2:$B$996=Москва!$E38)*[2]Indoor!$G$2:$G$996)),0)} -> 0
... D42: Indoor | J42: {=IF(H42>0,H42*G42,IF(I42>0,G42*I42*SUMPRODUCT(('[2]Коэфы качество контакта'!$A$2:$A$50=D42)*'[2]Коэфы качество контакта'!$G$2:$G$50),SUMPRODUCT(([2]Indoor!$A$2:$A$996=Москва!$E$4)*([2]Indoor!$B$2:$B$996=Москва!$E42)*[2]Indoor!$F$2:$F$996)*F42*G42))} -> 0 | N42: =M42*VLOOKUP(D42,'[2]Коэфы качество контакта'!$A$2:$E$22,3,FALSE)*VLOOKUP(D42,'[2]Коэфы качество контакта'!$A$2:$E$22,5,FALSE) -> 0 | O42: {=IFERROR(IF(I42>0,I42*G42,J42/SUMPRODUCT(([2]Indoor!$A$2:$A$996=Москва!$E$4)*([2]Indoor!$B$2:$B$996=Москва!$E42)*[2]Indoor!$G$2:$G$996)),0)} -> 0
D43: Метро | J43: =SUM(J44:J48) -> 0 | K43: Количество выходов в день | L43: Количество веток | M43: Хронометраж | N43: Время взаимодействия с креативом | O43: =IF(J43>0,J43/VLOOKUP(D43,'[2]Коэфы качество контакта'!$A$2:$G$22,7,FALSE),(1-(1-(O44/$E$3*0.5))*(1-(O45/$E$3*0.5))*(1-(O46/$E$3*0.5))*(1-(O47/$E$3*0.5))*(1-(O48/$E$3*0.5)))*$E$3) -> 0
D44: Метро | E44: Digital Screen в вагонах | J44: {=IF(H44>0,H44*G44,IF(K44>0,SUMPRODUCT((([2]Метро!$A$2:$A$1000=Москва!$E$4)*[2]Метро!$E$2:$E$1000)/1000)*L44*F44*G44*SUMPRODUCT(([2]Метро!$F$2:$F$6=Москва!$E44)*[2]Метро!$G$2:$G$6)*K44,IF(I44>0,G44*I44*SUMPRODUCT(('[2]Коэфы качество контакта'!$A$2:$A$50=D44)*'[2]Коэфы качество контакта'!$G$2:$G$50),"")))} | N44: =M44*VLOOKUP(D44,'[2]Коэфы качество контакта'!$A$2:$E$22,3,FALSE)*VLOOKUP(D44,'[2]Коэфы качество контакта'!$A$2:$E$22,5,FALSE) -> 0 | O44: =IFERROR(IF(I44>0,I44*G44,J44/VLOOKUP(D44,'[2]Коэфы качество контакта'!$A$2:$G$22,7,FALSE)),) -> 0
...

Sheet Списки
A1: Фильтр | B1: Список
A2: ГЕО | B2: Москва
A3: ГЕО | B3: Санкт-Петербург
A4: ГЕО | B4: Екатеринбург
A5: ГЕО | B5: Томск
A6: ГЕО | B6: Кемерово
A7: ГЕО | B7: Казань
A8: ГЕО | B8: Новосибирск
A9: ГЕО | B9: Краснодар
A10: ГЕО | B10: Сочи
A11: ГЕО | B11: Чебоксары
A12: ГЕО | B12: Нижний Новгород
... A19: Тип площадки | B19: Площадка

Sheet Описание
A1: Описание
A2: ООН
A3: Indoor
A4: Радио
A5: Digital
A6: Айдентика Бренда партнера на сайте
A7: PR
A8: Видео
A9: Брендирование
A10: Промо-акции
A11: Лого партнера
A12: BB
... A75: Блогеры в VK

Sheet Форматы
A1: Описание | B1: Форматы
A2: ООН | B2: BB
A3: ООН | B3: DBB
A4: ООН | B4: SS
A5: ООН | B5: DSS
A6: ООН | B6: CF
A7: ООН | B7: DCF
A8: ООН | B8: Медиафасады
A9: ООН | B9: PL
A10: Digital | B10: Видео
A11: Digital | B11: Баннеры
A12: Digital | B12: Аудио
... A65: PR | B65: Блогеры в VK

Sheet PR
A1: Sostav
A2: Marie Claire
A3: НСН
A4: Woman.ru
A5: Thegirl.ru
A6: The Blueprint
A7: AdIndex
A8: РБК
A9: Коммерсант
A10: Известия
A11: 100 тыс
A12: 200 тыс
... A16: 1 млн
